INFO     [02-04 14:56:22] #####Начало#####
ERROR    [02-04 14:56:33] Ошибка!
Traceback (most recent call last):
  File "D:\Ruslan\8. Pet-project\Python\atest1\1test.py", line 46, in <module>
    raise Exception()
Exception
INFO     [02-04 14:56:36] #####Конец#####
WARNING  [02-04 14:56:38] Retrying (Retry(total=2, connect=None, read=None, redirect=None, status=None)) after connection broken by 'NewConnectionError('<urllib3.connection.HTTPConnection object at 0x00000224DD345A60>: Failed to establish a new connection: [WinError 10061] Подключение не установлено, т.к. конечный компьютер отверг запрос на подключение')': /session/64b2d596b18a15012826a478ebb940ca
WARNING  [02-04 14:56:40] Retrying (Retry(total=1, connect=None, read=None, redirect=None, status=None)) after connection broken by 'NewConnectionError('<urllib3.connection.HTTPConnection object at 0x00000224DD3B3A30>: Failed to establish a new connection: [WinError 10061] Подключение не установлено, т.к. конечный компьютер отверг запрос на подключение')': /session/64b2d596b18a15012826a478ebb940ca
